[ 2025-04-14 23:31:29,509 ] 97 werkzeug - INFO - [31m[1mWARNING: This is a development server. Do not use it in a production deployment. Use a production WSGI server instead.[0m
 * Running on all addresses (0.0.0.0)
 * Running on http://127.0.0.1:5000
 * Running on http://10.0.0.216:5000
[ 2025-04-14 23:31:29,510 ] 97 werkzeug - INFO - [33mPress CTRL+C to quit[0m
[ 2025-04-14 23:31:34,722 ] 875 app - ERROR - Exception on /predictdata [POST]
Traceback (most recent call last):
  File "/Users/ishmael/Documents/covid_vaccine_risk/venv/lib/python3.11/site-packages/flask/app.py", line 1511, in wsgi_app
    response = self.full_dispatch_request()
               ^^^^^^^^^^^^^^^^^^^^^^^^^^^^
  File "/Users/ishmael/Documents/covid_vaccine_risk/venv/lib/python3.11/site-packages/flask/app.py", line 919, in full_dispatch_request
    rv = self.handle_user_exception(e)
         ^^^^^^^^^^^^^^^^^^^^^^^^^^^^^
  File "/Users/ishmael/Documents/covid_vaccine_risk/venv/lib/python3.11/site-packages/flask/app.py", line 917, in full_dispatch_request
    rv = self.dispatch_request()
         ^^^^^^^^^^^^^^^^^^^^^^^
  File "/Users/ishmael/Documents/covid_vaccine_risk/venv/lib/python3.11/site-packages/flask/app.py", line 902, in dispatch_request
    return self.ensure_sync(self.view_functions[rule.endpoint])(**view_args)  # type: ignore[no-any-return]
           ^^^^^^^^^^^^^^^^^^^^^^^^^^^^^^^^^^^^^^^^^^^^^^^^^^^^^^^^^^^^^^^^^
  File "/Users/ishmael/Documents/covid_vaccine_risk/app.py", line 23, in predict_datapoint
    data=CustomData(
         ^^^^^^^^^^^
TypeError: CustomData.__init__() missing 1 required positional argument: 'ai_predicted_score'
[ 2025-04-14 23:31:34,726 ] 97 werkzeug - INFO - 127.0.0.1 - - [14/Apr/2025 23:31:34] "[35m[1mPOST /predictdata HTTP/1.1[0m" 500 -
[ 2025-04-14 23:31:36,505 ] 97 werkzeug - INFO - 127.0.0.1 - - [14/Apr/2025 23:31:36] "GET /predictdata HTTP/1.1" 200 -
[ 2025-04-14 23:31:38,002 ] 97 werkzeug - INFO - 127.0.0.1 - - [14/Apr/2025 23:31:38] "GET /predictdata HTTP/1.1" 200 -
[ 2025-04-14 23:32:14,079 ] 875 app - ERROR - Exception on /predictdata [POST]
Traceback (most recent call last):
  File "/Users/ishmael/Documents/covid_vaccine_risk/venv/lib/python3.11/site-packages/flask/app.py", line 1511, in wsgi_app
    response = self.full_dispatch_request()
               ^^^^^^^^^^^^^^^^^^^^^^^^^^^^
  File "/Users/ishmael/Documents/covid_vaccine_risk/venv/lib/python3.11/site-packages/flask/app.py", line 919, in full_dispatch_request
    rv = self.handle_user_exception(e)
         ^^^^^^^^^^^^^^^^^^^^^^^^^^^^^
  File "/Users/ishmael/Documents/covid_vaccine_risk/venv/lib/python3.11/site-packages/flask/app.py", line 917, in full_dispatch_request
    rv = self.dispatch_request()
         ^^^^^^^^^^^^^^^^^^^^^^^
  File "/Users/ishmael/Documents/covid_vaccine_risk/venv/lib/python3.11/site-packages/flask/app.py", line 902, in dispatch_request
    return self.ensure_sync(self.view_functions[rule.endpoint])(**view_args)  # type: ignore[no-any-return]
           ^^^^^^^^^^^^^^^^^^^^^^^^^^^^^^^^^^^^^^^^^^^^^^^^^^^^^^^^^^^^^^^^^
  File "/Users/ishmael/Documents/covid_vaccine_risk/app.py", line 23, in predict_datapoint
    data=CustomData(
         ^^^^^^^^^^^
TypeError: CustomData.__init__() missing 1 required positional argument: 'ai_predicted_score'
[ 2025-04-14 23:32:14,081 ] 97 werkzeug - INFO - 127.0.0.1 - - [14/Apr/2025 23:32:14] "[35m[1mPOST /predictdata HTTP/1.1[0m" 500 -
