[ 2025-04-13 16:31:43,766 ] 41 root - INFO - Entered the data ingestion method or component
[ 2025-04-13 16:31:43,766 ] 22 root - INFO - Fetching data from Firebase: https://covid-vaccine-risk-default-rtdb.firebaseio.com/data.json
[ 2025-04-13 16:31:44,303 ] 46 root - INFO - Read the dataset as dataframe
[ 2025-04-13 16:31:44,313 ] 53 root - INFO - Preprocessing done
[ 2025-04-13 16:31:44,314 ] 56 root - INFO - Train test split done
[ 2025-04-13 16:31:44,318 ] 65 root - INFO - Inmgestion of the data is completed
[ 2025-04-13 16:31:44,321 ] 77 root - INFO - Read train and test data completed
[ 2025-04-13 16:31:44,321 ] 79 root - INFO - Obtaining preprocessing object
[ 2025-04-13 16:31:44,321 ] 57 root - INFO - Categorical columns: ['Blood Pressure', 'Diabetes Status', 'Gender', 'Location', 'Outcome', 'Pre-existing Conditions', 'Severity', 'Smoking History', 'Vaccine Dose']
[ 2025-04-13 16:31:44,321 ] 58 root - INFO - Numerical columns: ['Age', 'BMI', 'Cholesterol Level', 'Heart Attack Date_day', 'Heart Attack Date_day_of_week', 'Heart Attack Date_is_weekend', 'Heart Attack Date_month', 'Heart Attack Date_quarter', 'Heart Attack Date_year', 'Patient ID', 'Vaccination Date_day', 'Vaccination Date_day_of_week', 'Vaccination Date_is_weekend', 'Vaccination Date_month', 'Vaccination Date_quarter', 'Vaccination Date_year']
[ 2025-04-13 16:31:44,322 ] 91 root - INFO - Applying preprocessing object on training dataframe and testing dataframe.
[ 2025-04-13 16:31:44,331 ] 105 root - INFO - Saved preprocessing object.
[ 2025-04-13 16:31:44,331 ] 33 root - INFO - Split training and test input data
[ 2025-04-13 16:31:52,483 ] 8 root - ERROR - Error occured in python script name [/Users/ishmael/Documents/covid_vaccine_risk/src/utils.py] line number [64] error message[
All the 81 fits failed.
It is very likely that your model is misconfigured.
You can try to debug the error by setting error_score='raise'.

Below are more details about the failures:
--------------------------------------------------------------------------------
81 fits failed with the following error:
Traceback (most recent call last):
  File "/Users/ishmael/Documents/covid_vaccine_risk/venv/lib/python3.11/site-packages/sklearn/model_selection/_validation.py", line 866, in _fit_and_score
    estimator.fit(X_train, y_train, **fit_params)
  File "/Users/ishmael/Documents/covid_vaccine_risk/venv/lib/python3.11/site-packages/catboost/core.py", line 5873, in fit
    return self._fit(X, y, cat_features, text_features, embedding_features, None, graph, sample_weight, None, None, None, None, baseline,
           ^^^^^^^^^^^^^^^^^^^^^^^^^^^^^^^^^^^^^^^^^^^^^^^^^^^^^^^^^^^^^^^^^^^^^^^^^^^^^^^^^^^^^^^^^^^^^^^^^^^^^^^^^^^^^^^^^^^^^^^^^^^^^^
  File "/Users/ishmael/Documents/covid_vaccine_risk/venv/lib/python3.11/site-packages/catboost/core.py", line 2410, in _fit
    self._train(
  File "/Users/ishmael/Documents/covid_vaccine_risk/venv/lib/python3.11/site-packages/catboost/core.py", line 1790, in _train
    self._object._train(train_pool, test_pool, params, allow_clear_pool, init_model._object if init_model else None)
  File "_catboost.pyx", line 5017, in _catboost._CatBoost._train
  File "_catboost.pyx", line 5066, in _catboost._CatBoost._train
_catboost.CatBoostError: catboost/libs/metrics/metric.cpp:6930: All train targets are equal
]
[ 2025-04-13 16:31:52,483 ] 8 root - ERROR - Error occured in python script name [/Users/ishmael/Documents/covid_vaccine_risk/src/components/model_trainer.py] line number [87] error message[Error occured in python script name [/Users/ishmael/Documents/covid_vaccine_risk/src/utils.py] line number [64] error message[
All the 81 fits failed.
It is very likely that your model is misconfigured.
You can try to debug the error by setting error_score='raise'.

Below are more details about the failures:
--------------------------------------------------------------------------------
81 fits failed with the following error:
Traceback (most recent call last):
  File "/Users/ishmael/Documents/covid_vaccine_risk/venv/lib/python3.11/site-packages/sklearn/model_selection/_validation.py", line 866, in _fit_and_score
    estimator.fit(X_train, y_train, **fit_params)
  File "/Users/ishmael/Documents/covid_vaccine_risk/venv/lib/python3.11/site-packages/catboost/core.py", line 5873, in fit
    return self._fit(X, y, cat_features, text_features, embedding_features, None, graph, sample_weight, None, None, None, None, baseline,
           ^^^^^^^^^^^^^^^^^^^^^^^^^^^^^^^^^^^^^^^^^^^^^^^^^^^^^^^^^^^^^^^^^^^^^^^^^^^^^^^^^^^^^^^^^^^^^^^^^^^^^^^^^^^^^^^^^^^^^^^^^^^^^^
  File "/Users/ishmael/Documents/covid_vaccine_risk/venv/lib/python3.11/site-packages/catboost/core.py", line 2410, in _fit
    self._train(
  File "/Users/ishmael/Documents/covid_vaccine_risk/venv/lib/python3.11/site-packages/catboost/core.py", line 1790, in _train
    self._object._train(train_pool, test_pool, params, allow_clear_pool, init_model._object if init_model else None)
  File "_catboost.pyx", line 5017, in _catboost._CatBoost._train
  File "_catboost.pyx", line 5066, in _catboost._CatBoost._train
_catboost.CatBoostError: catboost/libs/metrics/metric.cpp:6930: All train targets are equal
]]
