[ 2025-04-14 14:10:55,579 ] 8 root - ERROR - Error occured in python script name [/Users/ishmael/Documents/covid_vaccine_risk/src/utils.py] line number [22] error message[HTTPSConnectionPool(host='www.kaggle.com', port=443): Max retries exceeded with url: /api/v1/datasets/view/samxsam/human-cognitive-performance-analysis (Caused by NameResolutionError("<urllib3.connection.HTTPSConnection object at 0x12792b490>: Failed to resolve 'www.kaggle.com' ([Errno 8] nodename nor servname provided, or not known)"))]
[ 2025-04-14 14:10:55,579 ] 8 root - ERROR - Error occured in python script name [/Users/ishmael/Documents/covid_vaccine_risk/src/components/data_ingestion.py] line number [43] error message[Error occured in python script name [/Users/ishmael/Documents/covid_vaccine_risk/src/utils.py] line number [22] error message[HTTPSConnectionPool(host='www.kaggle.com', port=443): Max retries exceeded with url: /api/v1/datasets/view/samxsam/human-cognitive-performance-analysis (Caused by NameResolutionError("<urllib3.connection.HTTPSConnection object at 0x12792b490>: Failed to resolve 'www.kaggle.com' ([Errno 8] nodename nor servname provided, or not known)"))]]
